<?xml version="1.0" encoding="UTF-8"?>
<testsuite errors="0" failures="1" name="MyFirstTests-20180527002531" skipped="0" tests="4" time="0.002" timestamp="2018-05-27T00:25:31">
	<testcase classname="MyFirstTests" name="test_five_return" time="0.001" timestamp="2018-05-27T00:25:31"/>
	<testcase classname="MyFirstTests" name="test_hello" time="0.000" timestamp="2018-05-27T00:25:31"/>
	<testcase classname="MyFirstTests" name="test_new_function" time="0.001" timestamp="2018-05-27T00:25:31"/>
	<testcase classname="MyFirstTests" name="test_bad_hello" time="0.001" timestamp="2018-05-27T00:25:31">
		<failure message="'Hello, Ashish!' != 'Hello, World!'
- Hello, Ashish!
+ Hello, World!
" type="AssertionError">
<![CDATA[Traceback (most recent call last):
  File "code_test.py", line 10, in test_bad_hello
    self.assertEqual('Hello, Ashish!', hello())
AssertionError: 'Hello, Ashish!' != 'Hello, World!'
- Hello, Ashish!
+ Hello, World!

]]>		</failure>
	</testcase>
	<system-out>
<![CDATA[]]>	</system-out>
	<system-err>
<![CDATA[]]>	</system-err>
</testsuite>
